Workbook

Sheet Medical History
A1: ID | B1: Data collection date | C1: Age | D1: Gender | E1: Name | F1: Hypertension | G1: Heart Disease | H1: Ever Married | I1: Work Type | J1: Residence Type | K1: Average Glucose Level | L1: BMI | M1: Smoking Status | N1: Physical Activity | O1: Dietary Habits | P1: Alcohol Consumption | Q1: Chronic Stress | R1: Sleep Hours | S1: Family History of Stroke | T1: Education Level | U1: Income Level | V1: Stroke Risk Score | W1: Region | X1: Stroke Occurrence | Y1: Age Group | Z1: Risk Level | AA1: High Risk Flag | AB1: Hypertension Label | AC1: Heart Disease Label | AD1: Alcohol Label | AE1: Stroke Label | AF1: Search Key
A2: 1 | B2: 45402 | C2: 78 | D2: Female | E2: A Roy | F2: 0 | G2: 0 | H2: 1 | I2: Private | J2: Rural | K2: 267.3 | L2: 36.2 | M2: Formerly smoked | N2: Sedentary | O2: Non-Vegetarian | P2: 0 | Q2: 0 | R2: 11 | S2: 0 | T2: Tertiary | U2: Middle | V2: 88 | W2: South | X2: 0 | Y2: =IF(C2<30,"<30",IF(C2<=50,"30-50","50+")) -> 50+ | Z2: =IF(V2>=70,"High",IF(V2>=40,"Medium","Low")) -> High | AA2: =IF(V2>=70,"Yes","No") -> Yes | AB2: =IF(F2=1,"Yes","No") -> No | AC2: =IF(G2=1,"Yes","No") -> No | AD2: =IF(P2=1,"Consumes Alcohol","No Alcohol") -> No Alcohol | AE2: =IF(X2=1,"Stroke","No Stroke") -> No Stroke | AF2: =A2&" - "&E2 -> 1 - A Roy
A3: 2 | B3: 45402 | C3: 60 | D3: Female | E3: A Shenoy | F3: 0 | G3: 0 | H3: 0 | I3: Private | J3: Rural | K3: 207.24 | L3: 19.8 | M3: Never smoked | N3: Light | O3: Vegetarian | P3: 0 | Q3: 0 | R3: 9 | S3: 0 | T3: Secondary | U3: High | V3: 56 | W3: East | X3: 0 | Y3: =IF(C3<30,"<30",IF(C3<=50,"30-50","50+")) -> 50+ | Z3: =IF(V3>=70,"High",IF(V3>=40,"Medium","Low")) -> Medium | AA3: =IF(V3>=70,"Yes","No") -> No | AB3: =IF(F3=1,"Yes","No") -> No | AC3: =IF(G3=1,"Yes","No") -> No | AD3: =IF(P3=1,"Consumes Alcohol","No Alcohol") -> No Alcohol | AE3: =IF(X3=1,"Stroke","No Stroke") -> No Stroke | AF3: =A3&" - "&E3 -> 2 - A Shenoy
A4: 3 | B4: 45402 | C4: 69 | D4: Male | E4: S Geloy | F4: 0 | G4: 0 | H4: 0 | I4: Private | J4: Urban | K4: 161.3 | L4: 34.5 | M4: Never smoked | N4: Sedentary | O4: Mixed | P4: 1 | Q4: 0 | R4: 3 | S4: 0 | T4: Secondary | U4: High | V4: 63 | W4: North | X4: 1 | Y4: =IF(C4<30,"<30",IF(C4<=50,"30-50","50+")) -> 50+ | Z4: =IF(V4>=70,"High",IF(V4>=40,"Medium","Low")) -> Medium | AA4: =IF(V4>=70,"Yes","No") -> No | AB4: =IF(F4=1,"Yes","No") -> No | AC4: =IF(G4=1,"Yes","No") -> No | AD4: =IF(P4=1,"Consumes Alcohol","No Alcohol") -> Consumes Alcohol | AE4: =IF(X4=1,"Stroke","No Stroke") -> Stroke | AF4: =A4&" - "&E4 -> 3 - S Geloy
A5: 4 | B5: 45402 | C5: 43 | D5: Male | E5: G Messy | F5: 0 | G5: 0 | H5: 1 | I5: Never Worked | J5: Urban | K5: 247.49 | L5: 48.8 | M5: Never smoked | N5: Active | O5: Mixed | P5: 0 | Q5: 1 | R5: 4 | S5: 0 | T5: Tertiary | U5: Middle | V5: 93 | W5: South | X5: 0 | Y5: =IF(C5<30,"<30",IF(C5<=50,"30-50","50+")) -> 30-50 | Z5: =IF(V5>=70,"High",IF(V5>=40,"Medium","Low")) -> High | AA5: =IF(V5>=70,"Yes","No") -> Yes | AB5: =IF(F5=1,"Yes","No") -> No | AC5: =IF(G5=1,"Yes","No") -> No | AD5: =IF(P5=1,"Consumes Alcohol","No Alcohol") -> No Alcohol | AE5: =IF(X5=1,"Stroke","No Stroke") -> No Stroke | AF5: =A5&" - "&E5 -> 4 - G Messy
A6: 5 | B6: 45403 | C6: 30 | D6: Female | E6: B Bern | F6: 0 | G6: 0 | H6: 1 | I6: Government | J6: Urban | K6: 116.57 | L6: 31.3 | M6: Formerly smoked | N6: Light | O6: Mixed | P6: 0 | Q6: 1 | R6: 9 | S6: 0 | T6: Secondary | U6: High | V6: 99 | W6: West | X6: 0 | Y6: =IF(C6<30,"<30",IF(C6<=50,"30-50","50+")) -> 30-50 | Z6: =IF(V6>=70,"High",IF(V6>=40,"Medium","Low")) -> High | AA6: =IF(V6>=70,"Yes","No") -> Yes | AB6: =IF(F6=1,"Yes","No") -> No | AC6: =IF(G6=1,"Yes","No") -> No | AD6: =IF(P6=1,"Consumes Alcohol","No Alcohol") -> No Alcohol | AE6: =IF(X6=1,"Stroke","No Stroke") -> No Stroke | AF6: =A6&" - "&E6 -> 5 - B Bern
A7: 6 | B7: 45404 | C7: 53 | D7: Male | E7: S Bush | F7: 1 | G7: 0 | H7: 1 | I7: Government | J7: Urban | K7: 220.62 | L7: 49.9 | M7: Never smoked | N7: Active | O7: Non-Vegetarian | P7: 0 | Q7: 1 | R7: 7 | S7: 0 | T7: No education | U7: Low | V7: 56 | W7: North | X7: 0 | Y7: =IF(C7<30,"<30",IF(C7<=50,"30-50","50+")) -> 50+ | Z7: =IF(V7>=70,"High",IF(V7>=40,"Medium","Low")) -> Medium | AA7: =IF(V7>=70,"Yes","No") -> No | AB7: =IF(F7=1,"Yes","No") -> Yes | AC7: =IF(G7=1,"Yes","No") -> No | AD7: =IF(P7=1,"Consumes Alcohol","No Alcohol") -> No Alcohol | AE7: =IF(X7=1,"Stroke","No Stroke") -> No Stroke | AF7: =A7&" - "&E7 -> 6 - S Bush
A8: 7 | B8: 45404 | C8: 83 | D8: Female | E8: W Bern | F8: 0 | G8: 0 | H8: 0 | I8: Children | J8: Urban | K8: 193.32 | L8: 46.8 | M8: Never smoked | N8: Sedentary | O8: Vegetarian | P8: 0 | Q8: 0 | R8: 5 | S8: 0 | T8: Secondary | U8: High | V8: 87 | W8: South | X8: 0 | Y8: =IF(C8<30,"<30",IF(C8<=50,"30-50","50+")) -> 50+ | Z8: =IF(V8>=70,"High",IF(V8>=40,"Medium","Low")) -> High | AA8: =IF(V8>=70,"Yes","No") -> Yes | AB8: =IF(F8=1,"Yes","No") -> No | AC8: =IF(G8=1,"Yes","No") -> No | AD8: =IF(P8=1,"Consumes Alcohol","No Alcohol") -> No Alcohol | AE8: =IF(X8=1,"Stroke","No Stroke") -> No Stroke | AF8: =A8&" - "&E8 -> 7 - W Bern
A9: 8 | B9: 45404 | C9: 43 | D9: Female | E9: N Jordan | F9: 0 | G9: 0 | H9: 0 | I9: Never Worked | J9: Urban | K9: 198.59 | L9: 23.3 | M9: Never smoked | N9: Light | O9: Mixed | P9: 0 | Q9: 0 | R9: 10 | S9: 0 | T9: Primary | U9: Low | V9: 5 | W9: North | X9: 0 | Y9: =IF(C9<30,"<30",IF(C9<=50,"30-50","50+")) -> 30-50 | Z9: =IF(V9>=70,"High",IF(V9>=40,"Medium","Low")) -> Low | AA9: =IF(V9>=70,"Yes","No") -> No | AB9: =IF(F9=1,"Yes","No") -> No | AC9: =IF(G9=1,"Yes","No") -> No | AD9: =IF(P9=1,"Consumes Alcohol","No Alcohol") -> No Alcohol | AE9: =IF(X9=1,"Stroke","No Stroke") -> No Stroke | AF9: =A9&" - "&E9 -> 8 - N Jordan
A10: 9 | B10: 45404 | C10: 62 | D10: Male | E10: M Jordan | F10: 1 | G10: 0 | H10: 0 | I10: Children | J10: Rural | K10: 117.81 | L10: 16.5 | M10: Unknown | N10: Sedentary | O10: Non-Vegetarian | P10: 1 | Q10: 0 | R10: 8 | S10: 1 | T10: Secondary | U10: Low | V10: 98 | W10: East | X10: 0 | Y10: =IF(C10<30,"<30",IF(C10<=50,"30-50","50+")) -> 50+ | Z10: =IF(V10>=70,"High",IF(V10>=40,"Medium","Low")) -> High | AA10: =IF(V10>=70,"Yes","No") -> Yes | AB10: =IF(F10=1,"Yes","No") -> Yes | AC10: =IF(G10=1,"Yes","No") -> No | AD10: =IF(P10=1,"Consumes Alcohol","No Alcohol") -> Consumes Alcohol | AE10: =IF(X10=1,"Stroke","No Stroke") -> No Stroke | AF10: =A10&" - "&E10 -> 9 - M Jordan
A11: 10 | B11: 45404 | C11: 35 | D11: Male | E11: A Sundar | F11: 0 | G11: 0 | H11: 0 | I11: Government | J11: Urban | K11: 289.09 | L11: 37 | M11: Never smoked | N11: Light | O11: Vegetarian | P11: 0 | Q11: 0 | R11: 8 | S11: 0 | T11: Tertiary | U11: Middle | V11: 94 | W11: East | X11: 0 | Y11: =IF(C11<30,"<30",IF(C11<=50,"30-50","50+")) -> 30-50 | Z11: =IF(V11>=70,"High",IF(V11>=40,"Medium","Low")) -> High | AA11: =IF(V11>=70,"Yes","No") -> Yes | AB11: =IF(F11=1,"Yes","No") -> No | AC11: =IF(G11=1,"Yes","No") -> No | AD11: =IF(P11=1,"Consumes Alcohol","No Alcohol") -> No Alcohol | AE11: =IF(X11=1,"Stroke","No Stroke") -> No Stroke | AF11: =A11&" - "&E11 -> 10 - A Sundar
A12: 11 | B12: 45408 | C12: 83 | D12: Male | E12: L Armstrong | F12: 0 | G12: 0 | H12: 1 | I12: Private | J12: Urban | K12: 150.86 | L12: 34.3 | M12: Never smoked | N12: Moderate | O12: Non-Vegetarian | P12: 0 | Q12: 0 | R12: 4 | S12: 0 | T12: Primary | U12: Middle | V12: 31 | W12: South | X12: 0 | Y12: =IF(C12<30,"<30",IF(C12<=50,"30-50","50+")) -> 50+ | Z12: =IF(V12>=70,"High",IF(V12>=40,"Medium","Low")) -> Low | AA12: =IF(V12>=70,"Yes","No") -> No | AB12: =IF(F12=1,"Yes","No") -> No | AC12: =IF(G12=1,"Yes","No") -> No | AD12: =IF(P12=1,"Consumes Alcohol","No Alcohol") -> No Alcohol | AE12: =IF(X12=1,"Stroke","No Stroke") -> No Stroke | AF12: =A12&" - "&E12 -> 11 - L Armstrong
A13: 12 | B13: 45409 | C13: 71 | D13: Male | E13: M Fritzler | F13: 0 | G13: 0 | H13: 1 | I13: Private | J13: Urban | K13: 254.9 | L13: 49.5 | M13: Never smoked | N13: Light | O13: Non-Vegetarian | P13: 0 | Q13: 0 | R13: 6 | S13: 1 | T13: Secondary | U13: High | V13: 30 | W13: South | X13: 0 | Y13: =IF(C13<30,"<30",IF(C13<=50,"30-50","50+")) -> 50+ | Z13: =IF(V13>=70,"High",IF(V13>=40,"Medium","Low")) -> Low | AA13: =IF(V13>=70,"Yes","No") -> No | AB13: =IF(F13=1,"Yes","No") -> No | AC13: =IF(G13=1,"Yes","No") -> No | AD13: =IF(P13=1,"Consumes Alcohol","No Alcohol") -> No Alcohol | AE13: =IF(X13=1,"Stroke","No Stroke") -> No Stroke | AF13: =A13&" - "&E13 -> 12 - M Fritzler
... A97: 96 | B97: 45484 | C97: 65 | D97: Male | E97: J Barnett | F97: 0 | G97: 0 | H97: 0 | I97: Private | J97: Urban | K97: 172.53 | L97: 28.1 | M97: Unknown | N97: Sedentary | O97: Vegetarian | P97: 0 | Q97: 0 | R97: 12 | S97: 0 | T97: Primary | U97: Low | V97: 73 | W97: East | X97: 0 | Y97: =IF(C97<30,"<30",IF(C97<=50,"30-50","50+")) -> 50+ | Z97: =IF(V97>=70,"High",IF(V97>=40,"Medium","Low")) -> High | AA97: =IF(V97>=70,"Yes","No") -> Yes | AB97: =IF(F97=1,"Yes","No") -> No | AC97: =IF(G97=1,"Yes","No") -> No | AD97: =IF(P97=1,"Consumes Alcohol","No Alcohol") -> No Alcohol | AE97: =IF(X97=1,"Stroke","No Stroke") -> No Stroke | AF97: =A97&" - "&E97 -> 96 - J Barnett

Sheet Dashboard Data
A1: KPI | B1: Value
A2: Total Patients | B2: {=SUMPRODUCT((--(Medical_History[ID]<>"")*IF(Dashboard!$F$12="All",1,--(Medical_History[Gender]=Dashboard!$F$12))*IF(Dashboard!$H$12="All",1,--(Medical_History[Age Group]=Dashboard!$H$12))*IF(Dashboard!$J$12="All",1,--(Medical_History[Region]=Dashboard!$J$12))*IF(Dashboard!$L$12="All",1,--(Medical_History[Smoking Status]=Dashboard!$L$12))*IF(Dashboard!$N$12="All",1,--(Medical_History[Dietary Habits]=Dashboard!$N$12))*IF(Dashboard!$P$12="All",1,--(Medical_History[Alcohol Label]=Dashboard!$P$12))*IF(Dashboard!$F$14="All",1,--(Medical_History[Hypertension Label]=Dashboard!$F$14))*IF(Dashboard!$H$14="All",1,--(Medical_History[Heart Disease Label]=Dashboard!$H$14))*IF(Dashboard!$J$14="All",1,--(Medical_History[Residence Type]=Dashboard!$J$14))*IF(Dashboard!$L$14="All",1,--(Medical_History[Risk Level]=Dashboard!$L$14))*IF(Dashboard!$N$14="All",1,--(Medical_History[Stroke Label]=Dashboard!$N$14)) )*(1))} -> 39
A3: Average Stroke Risk Score | B3: {=IFERROR(SUMPRODUCT((--(Medical_History[ID]<>"")*IF(Dashboard!$F$12="All",1,--(Medical_History[Gender]=Dashboard!$F$12))*IF(Dashboard!$H$12="All",1,--(Medical_History[Age Group]=Dashboard!$H$12))*IF(Dashboard!$J$12="All",1,--(Medical_History[Region]=Dashboard!$J$12))*IF(Dashboard!$L$12="All",1,--(Medical_History[Smoking Status]=Dashboard!$L$12))*IF(Dashboard!$N$12="All",1,--(Medical_History[Dietary Habits]=Dashboard!$N$12))*IF(Dashboard!$P$12="All",1,--(Medical_History[Alcohol Label]=Dashboard!$P$12))*IF(Dashboard!$F$14="All",1,--(Medical_History[Hypertension Label]=Dashboard!$F$14))*IF(Dashboard!$H$14="All",1,--(Medical_History[Heart Disease Label]=Dashboard!$H$14))*IF(Dashboard!$J$14="All",1,--(Medical_History[Residence Type]=Dashboard!$J$14))*IF(Dashboard!$L$14="All",1,--(Medical_History[Risk Level]=Dashboard!$L$14))*IF(Dashboard!$N$14="All",1,--(Medical_History[Stroke Label]=Dashboard!$N$14)) )*(1)*Medical_History[Stroke Risk Score])/SUMPRODUCT((--(Medical_History[ID]<>"")*IF(Dashboard!$F$12="All",1,--(Medical_History[Gender]=Dashboard!$F$12))*IF(Dashboard!$H$12="All",1,--(Medical_History[Age Group]=Dashboard!$H$12))*IF(Dashboard!$J$12="All",1,--(Medical_History[Region]=Dashboard!$J$12))*IF(Dashboard!$L$12="All",1,--(Medical_History[Smoking Status]=Dashboard!$L$12))*IF(Dashboard!$N$12="All",1,--(Medical_History[Dietary Habits]=Dashboard!$N$12))*IF(Dashboard!$P$12="All",1,--(Medical_History[Alcohol Label]=Dashboard!$P$12))*IF(Dashboard!$F$14="All",1,--(Medical_History[Hypertension Label]=Dashboard!$F$14))*IF(Dashboard!$H$14="All",1,--(Medical_History[Heart Disease Label]=Dashboard!$H$14))*IF(Dashboard!$J$14="All",1,--(Medical_History[Residence Type]=Dashboard!$J$14))*IF(Dashboard!$L$14="All",1,--(Medical_History[Risk Level]=Dashboard!$L$14))*IF(Dashboard!$N$14="All",1,--(Medical_History[Stroke Label]=Dashboard!$N$14)) )*(1)),0)} -> 55.25641
A4: High-Risk Patients % | B4: {=IFERROR(SUMPRODUCT((--(Medical_History[ID]<>"")*IF(Dashboard!$F$12="All",1,--(Medical_History[Gender]=Dashboard!$F$12))*IF(Dashboard!$H$12="All",1,--(Medical_History[Age Group]=Dashboard!$H$12))*IF(Dashboard!$J$12="All",1,--(Medical_History[Region]=Dashboard!$J$12))*IF(Dashboard!$L$12="All",1,--(Medical_History[Smoking Status]=Dashboard!$L$12))*IF(Dashboard!$N$12="All",1,--(Medical_History[Dietary Habits]=Dashboard!$N$12))*IF(Dashboard!$P$12="All",1,--(Medical_History[Alcohol Label]=Dashboard!$P$12))*IF(Dashboard!$F$14="All",1,--(Medical_History[Hypertension Label]=Dashboard!$F$14))*IF(Dashboard!$H$14="All",1,--(Medical_History[Heart Disease Label]=Dashboard!$H$14))*IF(Dashboard!$J$14="All",1,--(Medical_History[Residence Type]=Dashboard!$J$14))*IF(Dashboard!$L$14="All",1,--(Medical_History[Risk Level]=Dashboard!$L$14))*IF(Dashboard!$N$14="All",1,--(Medical_History[Stroke Label]=Dashboard!$N$14)) )*--(Medical_History[Stroke Risk Score]>=70))/B2,0)} -> 0.41025641
A5: Stroke Occurrence Count | B5: {=SUMPRODUCT((--(Medical_History[ID]<>"")*IF(Dashboard!$F$12="All",1,--(Medical_History[Gender]=Dashboard!$F$12))*IF(Dashboard!$H$12="All",1,--(Medical_History[Age Group]=Dashboard!$H$12))*IF(Dashboard!$J$12="All",1,--(Medical_History[Region]=Dashboard!$J$12))*IF(Dashboard!$L$12="All",1,--(Medical_History[Smoking Status]=Dashboard!$L$12))*IF(Dashboard!$N$12="All",1,--(Medical_History[Dietary Habits]=Dashboard!$N$12))*IF(Dashboard!$P$12="All",1,--(Medical_History[Alcohol Label]=Dashboard!$P$12))*IF(Dashboard!$F$14="All",1,--(Medical_History[Hypertension Label]=Dashboard!$F$14))*IF(Dashboard!$H$14="All",1,--(Medical_History[Heart Disease Label]=Dashboard!$H$14))*IF(Dashboard!$J$14="All",1,--(Medical_History[Residence Type]=Dashboard!$J$14))*IF(Dashboard!$L$14="All",1,--(Medical_History[Risk Level]=Dashboard!$L$14))*IF(Dashboard!$N$14="All",1,--(Medical_History[Stroke Label]=Dashboard!$N$14)) )*(1)*Medical_History[Stroke Occurrence])} -> 1
A6: Highest Risk Segment | B6: =INDEX(D11:D13,MATCH(MAX(E11:E13),E11:E13,0)) -> <30
A7: Top Region by Cases | B7: =INDEX(K31:K34,MATCH(MAX(L31:L34),L31:L34,0)) -> South
D10: Age Group | E10: Avg Risk Score | F10: Stroke Cases | H10: Gender | I10: Avg Risk Score | J10: Stroke Cases
D11: <30 | E11: {=IFERROR(SUMPRODUCT((--(Medical_History[ID]<>"")*IF(Dashboard!$F$12="All",1,--(Medical_History[Gender]=Dashboard!$F$12))*IF(Dashboard!$H$12="All",1,--(Medical_History[Age Group]=Dashboard!$H$12))*IF(Dashboard!$J$12="All",1,--(Medical_History[Region]=Dashboard!$J$12))*IF(Dashboard!$L$12="All",1,--(Medical_History[Smoking Status]=Dashboard!$L$12))*IF(Dashboard!$N$12="All",1,--(Medical_History[Dietary Habits]=Dashboard!$N$12))*IF(Dashboard!$P$12="All",1,--(Medical_History[Alcohol Label]=Dashboard!$P$12))*IF(Dashboard!$F$14="All",1,--(Medical_History[Hypertension Label]=Dashboard!$F$14))*IF(Dashboard!$H$14="All",1,--(Medical_History[Heart Disease Label]=Dashboard!$H$14))*IF(Dashboard!$J$14="All",1,--(Medical_History[Residence Type]=Dashboard!$J$14))*IF(Dashboard!$L$14="All",1,--(Medical_History[Risk Level]=Dashboard!$L$14))*IF(Dashboard!$N$14="All",1,--(Medical_History[Stroke Label]=Dashboard!$N$14)) )*(--(Medical_History[Age Group]=D11))*Medical_History[Stroke Risk Score])/SUMPRODUCT((--(Medical_History[ID]<>"")*IF(Dashboard!$F$12="All",1,--(Medical_History[Gender]=Dashboard!$F$12))*IF(Dashboard!$H$12="All",1,--(Medical_History[Age Group]=Dashboard!$H$12))*IF(Dashboard!$J$12="All",1,--(Medical_History[Region]=Dashboard!$J$12))*IF(Dashboard!$L$12="All",1,--(Medical_History[Smoking Status]=Dashboard!$L$12))*IF(Dashboard!$N$12="All",1,--(Medical_History[Dietary Habits]=Dashboard!$N$12))*IF(Dashboard!$P$12="All",1,--(Medical_History[Alcohol Label]=Dashboard!$P$12))*IF(Dashboard!$F$14="All",1,--(Medical_History[Hypertension Label]=Dashboard!$F$14))*IF(Dashboard!$H$14="All",1,--(Medical_History[Heart Disease Label]=Dashboard!$H$14))*IF(Dashboard!$J$14="All",1,--(Medical_History[Residence Type]=Dashboard!$J$14))*IF(Dashboard!$L$14="All",1,--(Medical_History[Risk Level]=Dashboard!$L$14))*IF(Dashboard!$N$14="All",1,--(Medical_History[Stroke Label]=Dashboard!$N$14)) )*(--(Medical_History[Age Group]=D11))),0)} -> 70.75 | F11: {=SUMPRODUCT((--(Medical_History[ID]<>"")*IF(Dashboard!$F$12="All",1,--(Medical_History[Gender]=Dashboard!$F$12))*IF(Dashboard!$H$12="All",1,--(Medical_History[Age Group]=Dashboard!$H$12))*IF(Dashboard!$J$12="All",1,--(Medical_History[Region]=Dashboard!$J$12))*IF(Dashboard!$L$12="All",1,--(Medical_History[Smoking Status]=Dashboard!$L$12))*IF(Dashboard!$N$12="All",1,--(Medical_History[Dietary Habits]=Dashboard!$N$12))*IF(Dashboard!$P$12="All",1,--(Medical_History[Alcohol Label]=Dashboard!$P$12))*IF(Dashboard!$F$14="All",1,--(Medical_History[Hypertension Label]=Dashboard!$F$14))*IF(Dashboard!$H$14="All",1,--(Medical_History[Heart Disease Label]=Dashboard!$H$14))*IF(Dashboard!$J$14="All",1,--(Medical_History[Residence Type]=Dashboard!$J$14))*IF(Dashboard!$L$14="All",1,--(Medical_History[Risk Level]=Dashboard!$L$14))*IF(Dashboard!$N$14="All",1,--(Medical_History[Stroke Label]=Dashboard!$N$14)) )*(--(Medical_History[Age Group]=D11))*Medical_History[Stroke Occurrence])} -> 0 | H11: Female | I11: {=IFERROR(SUMPRODUCT((--(Medical_History[ID]<>"")*IF(Dashboard!$F$12="All",1,--(Medical_History[Gender]=Dashboard!$F$12))*IF(Dashboard!$H$12="All",1,--(Medical_History[Age Group]=Dashboard!$H$12))*IF(Dashboard!$J$12="All",1,--(Medical_History[Region]=Dashboard!$J$12))*IF(Dashboard!$L$12="All",1,--(Medical_History[Smoking Status]=Dashboard!$L$12))*IF(Dashboard!$N$12="All",1,--(Medical_History[Dietary Habits]=Dashboard!$N$12))*IF(Dashboard!$P$12="All",1,--(Medical_History[Alcohol Label]=Dashboard!$P$12))*IF(Dashboard!$F$14="All",1,--(Medical_History[Hypertension Label]=Dashboard!$F$14))*IF(Dashboard!$H$14="All",1,--(Medical_History[Heart Disease Label]=Dashboard!$H$14))*IF(Dashboard!$J$14="All",1,--(Medical_History[Residence Type]=Dashboard!$J$14))*IF(Dashboard!$L$14="All",1,--(Medical_History[Risk Level]=Dashboard!$L$14))*IF(Dashboard!$N$14="All",1,--(Medical_History[Stroke Label]=Dashboard!$N$14)) )*(--(Medical_History[Gender]=H11))*Medical_History[Stroke Risk Score])/SUMPRODUCT((--(Medical_History[ID]<>"")*IF(Dashboard!$F$12="All",1,--(Medical_History[Gender]=Dashboard!$F$12))*IF(Dashboard!$H$12="All",1,--(Medical_History[Age Group]=Dashboard!$H$12))*IF(Dashboard!$J$12="All",1,--(Medical_History[Region]=Dashboard!$J$12))*IF(Dashboard!$L$12="All",1,--(Medical_History[Smoking Status]=Dashboard!$L$12))*IF(Dashboard!$N$12="All",1,--(Medical_History[Dietary Habits]=Dashboard!$N$12))*IF(Dashboard!$P$12="All",1,--(Medical_History[Alcohol Label]=Dashboard!$P$12))*IF(Dashboard!$F$14="All",1,--(Medical_History[Hypertension Label]=Dashboard!$F$14))*IF(Dashboard!$H$14="All",1,--(Medical_History[Heart Disease Label]=Dashboard!$H$14))*IF(Dashboard!$J$14="All",1,--(Medical_History[Residence Type]=Dashboard!$J$14))*IF(Dashboard!$L$14="All",1,--(Medical_History[Risk Level]=Dashboard!$L$14))*IF(Dashboard!$N$14="All",1,--(Medical_History[Stroke Label]=Dashboard!$N$14)) )*(--(Medical_History[Gender]=H11))),0)} -> 55.25641 | J11: {=SUMPRODUCT((--(Medical_History[ID]<>"")*IF(Dashboard!$F$12="All",1,--(Medical_History[Gender]=Dashboard!$F$12))*IF(Dashboard!$H$12="All",1,--(Medical_History[Age Group]=Dashboard!$H$12))*IF(Dashboard!$J$12="All",1,--(Medical_History[Region]=Dashboard!$J$12))*IF(Dashboard!$L$12="All",1,--(Medical_History[Smoking Status]=Dashboard!$L$12))*IF(Dashboard!$N$12="All",1,--(Medical_History[Dietary Habits]=Dashboard!$N$12))*IF(Dashboard!$P$12="All",1,--(Medical_History[Alcohol Label]=Dashboard!$P$12))*IF(Dashboard!$F$14="All",1,--(Medical_History[Hypertension Label]=Dashboard!$F$14))*IF(Dashboard!$H$14="All",1,--(Medical_History[Heart Disease Label]=Dashboard!$H$14))*IF(Dashboard!$J$14="All",1,--(Medical_History[Residence Type]=Dashboard!$J$14))*IF(Dashboard!$L$14="All",1,--(Medical_History[Risk Level]=Dashboard!$L$14))*IF(Dashboard!$N$14="All",1,--(Medical_History[Stroke Label]=Dashboard!$N$14)) )*(--(Medical_History[Gender]=H11))*Medical_History[Stroke Occurrence])} -> 1
D12: 30-50 | E12: {=IFERROR(SUMPRODUCT((--(Medical_History[ID]<>"")*IF(Dashboard!$F$12="All",1,--(Medical_History[Gender]=Dashboard!$F$12))*IF(Dashboard!$H$12="All",1,--(Medical_History[Age Group]=Dashboard!$H$12))*IF(Dashboard!$J$12="All",1,--(Medical_History[Region]=Dashboard!$J$12))*IF(Dashboard!$L$12="All",1,--(Medical_History[Smoking Status]=Dashboard!$L$12))*IF(Dashboard!$N$12="All",1,--(Medical_History[Dietary Habits]=Dashboard!$N$12))*IF(Dashboard!$P$12="All",1,--(Medical_History[Alcohol Label]=Dashboard!$P$12))*IF(Dashboard!$F$14="All",1,--(Medical_History[Hypertension Label]=Dashboard!$F$14))*IF(Dashboard!$H$14="All",1,--(Medical_History[Heart Disease Label]=Dashboard!$H$14))*IF(Dashboard!$J$14="All",1,--(Medical_History[Residence Type]=Dashboard!$J$14))*IF(Dashboard!$L$14="All",1,--(Medical_History[Risk Level]=Dashboard!$L$14))*IF(Dashboard!$N$14="All",1,--(Medical_History[Stroke Label]=Dashboard!$N$14)) )*(--(Medical_History[Age Group]=D12))*Medical_History[Stroke Risk Score])/SUMPRODUCT((--(Medical_History[ID]<>"")*IF(Dashboard!$F$12="All",1,--(Medical_History[Gender]=Dashboard!$F$12))*IF(Dashboard!$H$12="All",1,--(Medical_History[Age Group]=Dashboard!$H$12))*IF(Dashboard!$J$12="All",1,--(Medical_History[Region]=Dashboard!$J$12))*IF(Dashboard!$L$12="All",1,--(Medical_History[Smoking Status]=Dashboard!$L$12))*IF(Dashboard!$N$12="All",1,--(Medical_History[Dietary Habits]=Dashboard!$N$12))*IF(Dashboard!$P$12="All",1,--(Medical_History[Alcohol Label]=Dashboard!$P$12))*IF(Dashboard!$F$14="All",1,--(Medical_History[Hypertension Label]=Dashboard!$F$14))*IF(Dashboard!$H$14="All",1,--(Medical_History[Heart Disease Label]=Dashboard!$H$14))*IF(Dashboard!$J$14="All",1,--(Medical_History[Residence Type]=Dashboard!$J$14))*IF(Dashboard!$L$14="All",1,--(Medical_History[Risk Level]=Dashboard!$L$14))*IF(Dashboard!$N$14="All",1,--(Medical_History[Stroke Label]=Dashboard!$N$14)) )*(--(Medical_History[Age Group]=D12))),0)} -> 55.538462 | F12: {=SUMPRODUCT((--(Medical_History[ID]<>"")*IF(Dashboard!$F$12="All",1,--(Medical_History[Gender]=Dashboard!$F$12))*IF(Dashboard!$H$12="All",1,--(Medical_History[Age Group]=Dashboard!$H$12))*IF(Dashboard!$J$12="All",1,--(Medical_History[Region]=Dashboard!$J$12))*IF(Dashboard!$L$12="All",1,--(Medical_History[Smoking Status]=Dashboard!$L$12))*IF(Dashboard!$N$12="All",1,--(Medical_History[Dietary Habits]=Dashboard!$N$12))*IF(Dashboard!$P$12="All",1,--(Medical_History[Alcohol Label]=Dashboard!$P$12))*IF(Dashboard!$F$14="All",1,--(Medical_History[Hypertension Label]=Dashboard!$F$14))*IF(Dashboard!$H$14="All",1,--(Medical_History[Heart Disease Label]=Dashboard!$H$14))*IF(Dashboard!$J$14="All",1,--(Medical_History[Residence Type]=Dashboard!$J$14))*IF(Dashboard!$L$14="All",1,--(Medical_History[Risk Level]=Dashboard!$L$14))*IF(Dashboard!$N$14="All",1,--(Medical_History[Stroke Label]=Dashboard!$N$14)) )*(--(Medical_History[Age Group]=D12))*Medical_History[Stroke Occurrence])} -> 0 | H12: Male | I12: {=IFERROR(SUMPRODUCT((--(Medical_History[ID]<>"")*IF(Dashboard!$F$12="All",1,--(Medical_History[Gender]=Dashboard!$F$12))*IF(Dashboard!$H$12="All",1,--(Medical_History[Age Group]=Dashboard!$H$12))*IF(Dashboard!$J$12="All",1,--(Medical_History[Region]=Dashboard!$J$12))*IF(Dashboard!$L$12="All",1,--(Medical_History[Smoking Status]=Dashboard!$L$12))*IF(Dashboard!$N$12="All",1,--(Medical_History[Dietary Habits]=Dashboard!$N$12))*IF(Dashboard!$P$12="All",1,--(Medical_History[Alcohol Label]=Dashboard!$P$12))*IF(Dashboard!$F$14="All",1,--(Medical_History[Hypertension Label]=Dashboard!$F$14))*IF(Dashboard!$H$14="All",1,--(Medical_History[Heart Disease Label]=Dashboard!$H$14))*IF(Dashboard!$J$14="All",1,--(Medical_History[Residence Type]=Dashboard!$J$14))*IF(Dashboard!$L$14="All",1,--(Medical_History[Risk Level]=Dashboard!$L$14))*IF(Dashboard!$N$14="All",1,--(Medical_History[Stroke Label]=Dashboard!$N$14)) )*(--(Medical_History[Gender]=H12))*Medical_History[Stroke Risk Score])/SUMPRODUCT((--(Medical_History[ID]<>"")*IF(Dashboard!$F$12="All",1,--(Medical_History[Gender]=Dashboard!$F$12))*IF(Dashboard!$H$12="All",1,--(Medical_History[Age Group]=Dashboard!$H$12))*IF(Dashboard!$J$12="All",1,--(Medical_History[Region]=Dashboard!$J$12))*IF(Dashboard!$L$12="All",1,--(Medical_History[Smoking Status]=Dashboard!$L$12))*IF(Dashboard!$N$12="All",1,--(Medical_History[Dietary Habits]=Dashboard!$N$12))*IF(Dashboard!$P$12="All",1,--(Medical_History[Alcohol Label]=Dashboard!$P$12))*IF(Dashboard!$F$14="All",1,--(Medical_History[Hypertension Label]=Dashboard!$F$14))*IF(Dashboard!$H$14="All",1,--(Medical_History[Heart Disease Label]=Dashboard!$H$14))*IF(Dashboard!$J$14="All",1,--(Medical_History[Residence Type]=Dashboard!$J$14))*IF(Dashboard!$L$14="All",1,--(Medical_History[Risk Level]=Dashboard!$L$14))*IF(Dashboard!$N$14="All",1,--(Medical_History[Stroke Label]=Dashboard!$N$14)) )*(--(Medical_History[Gender]=H12))),0)} -> 0 | J12: {=SUMPRODUCT((--(Medical_History[ID]<>"")*IF(Dashboard!$F$12="All",1,--(Medical_History[Gender]=Dashboard!$F$12))*IF(Dashboard!$H$12="All",1,--(Medical_History[Age Group]=Dashboard!$H$12))*IF(Dashboard!$J$12="All",1,--(Medical_History[Region]=Dashboard!$J$12))*IF(Dashboard!$L$12="All",1,--(Medical_History[Smoking Status]=Dashboard!$L$12))*IF(Dashboard!$N$12="All",1,--(Medical_History[Dietary Habits]=Dashboard!$N$12))*IF(Dashboard!$P$12="All",1,--(Medical_History[Alcohol Label]=Dashboard!$P$12))*IF(Dashboard!$F$14="All",1,--(Medical_History[Hypertension Label]=Dashboard!$F$14))*IF(Dashboard!$H$14="All",1,--(Medical_History[Heart Disease Label]=Dashboard!$H$14))*IF(Dashboard!$J$14="All",1,--(Medical_History[Residence Type]=Dashboard!$J$14))*IF(Dashboard!$L$14="All",1,--(Medical_History[Risk Level]=Dashboard!$L$14))*IF(Dashboard!$N$14="All",1,--(Medical_History[Stroke Label]=Dashboard!$N$14)) )*(--(Medical_History[Gender]=H12))*Medical_History[Stroke Occurrence])} -> 0
D13: 50+ | E13: {=IFERROR(SUMPRODUCT((--(Medical_History[ID]<>"")*IF(Dashboard!$F$12="All",1,--(Medical_History[Gender]=Dashboard!$F$12))*IF(Dashboard!$H$12="All",1,--(Medical_History[Age Group]=Dashboard!$H$12))*IF(Dashboard!$J$12="All",1,--(Medical_History[Region]=Dashboard!$J$12))*IF(Dashboard!$L$12="All",1,--(Medical_History[Smoking Status]=Dashboard!$L$12))*IF(Dashboard!$N$12="All",1,--(Medical_History[Dietary Habits]=Dashboard!$N$12))*IF(Dashboard!$P$12="All",1,--(Medical_History[Alcohol Label]=Dashboard!$P$12))*IF(Dashboard!$F$14="All",1,--(Medical_History[Hypertension Label]=Dashboard!$F$14))*IF(Dashboard!$H$14="All",1,--(Medical_History[Heart Disease Label]=Dashboard!$H$14))*IF(Dashboard!$J$14="All",1,--(Medical_History[Residence Type]=Dashboard!$J$14))*IF(Dashboard!$L$14="All",1,--(Medical_History[Risk Level]=Dashboard!$L$14))*IF(Dashboard!$N$14="All",1,--(Medical_History[Stroke Label]=Dashboard!$N$14)) )*(--(Medical_History[Age Group]=D13))*Medical_History[Stroke Risk Score])/SUMPRODUCT((--(Medical_History[ID]<>"")*IF(Dashboard!$F$12="All",1,--(Medical_History[Gender]=Dashboard!$F$12))*IF(Dashboard!$H$12="All",1,--(Medical_History[Age Group]=Dashboard!$H$12))*IF(Dashboard!$J$12="All",1,--(Medical_History[Region]=Dashboard!$J$12))*IF(Dashboard!$L$12="All",1,--(Medical_History[Smoking Status]=Dashboard!$L$12))*IF(Dashboard!$N$12="All",1,--(Medical_History[Dietary Habits]=Dashboard!$N$12))*IF(Dashboard!$P$12="All",1,--(Medical_History[Alcohol Label]=Dashboard!$P$12))*IF(Dashboard!$F$14="All",1,--(Medical_History[Hypertension Label]=Dashboard!$F$14))*IF(Dashboard!$H$14="All",1,--(Medical_History[Heart Disease Label]=Dashboard!$H$14))*IF(Dashboard!$J$14="All",1,--(Medical_History[Residence Type]=Dashboard!$J$14))*IF(Dashboard!$L$14="All",1,--(Medical_History[Risk Level]=Dashboard!$L$14))*IF(Dashboard!$N$14="All",1,--(Medical_History[Stroke Label]=Dashboard!$N$14)) )*(--(Medical_History[Age Group]=D13))),0)} -> 52.272727 | F13: {=SUMPRODUCT((--(Medical_History[ID]<>"")*IF(Dashboard!$F$12="All",1,--(Medical_History[Gender]=Dashboard!$F$12))*IF(Dashboard!$H$12="All",1,--(Medical_History[Age Group]=Dashboard!$H$12))*IF(Dashboard!$J$12="All",1,--(Medical_History[Region]=Dashboard!$J$12))*IF(Dashboard!$L$12="All",1,--(Medical_History[Smoking Status]=Dashboard!$L$12))*IF(Dashboard!$N$12="All",1,--(Medical_History[Dietary Habits]=Dashboard!$N$12))*IF(Dashboard!$P$12="All",1,--(Medical_History[Alcohol Label]=Dashboard!$P$12))*IF(Dashboard!$F$14="All",1,--(Medical_History[Hypertension Label]=Dashboard!$F$14))*IF(Dashboard!$H$14="All",1,--(Medical_History[Heart Disease Label]=Dashboard!$H$14))*IF(Dashboard!$J$14="All",1,--(Medical_History[Residence Type]=Dashboard!$J$14))*IF(Dashboard!$L$14="All",1,--(Medical_History[Risk Level]=Dashboard!$L$14))*IF(Dashboard!$N$14="All",1,--(Medical_History[Stroke Label]=Dashboard!$N$14)) )*(--(Medical_History[Age Group]=D13))*Medical_History[Stroke Occurrence])} -> 1
D16: Smoking Status | E16: Avg Risk Score | F16: Patients | H16: Diet Type | I16: Avg Risk Score | J16: Patients | L16: Alcohol | M16: Stroke Cases | N16: Avg Risk Score
D17: Never smoked | E17: {=IFERROR(SUMPRODUCT((--(Medical_History[ID]<>"")*IF(Dashboard!$F$12="All",1,--(Medical_History[Gender]=Dashboard!$F$12))*IF(Dashboard!$H$12="All",1,--(Medical_History[Age Group]=Dashboard!$H$12))*IF(Dashboard!$J$12="All",1,--(Medical_History[Region]=Dashboard!$J$12))*IF(Dashboard!$L$12="All",1,--(Medical_History[Smoking Status]=Dashboard!$L$12))*IF(Dashboard!$N$12="All",1,--(Medical_History[Dietary Habits]=Dashboard!$N$12))*IF(Dashboard!$P$12="All",1,--(Medical_History[Alcohol Label]=Dashboard!$P$12))*IF(Dashboard!$F$14="All",1,--(Medical_History[Hypertension Label]=Dashboard!$F$14))*IF(Dashboard!$H$14="All",1,--(Medical_History[Heart Disease Label]=Dashboard!$H$14))*IF(Dashboard!$J$14="All",1,--(Medical_History[Residence Type]=Dashboard!$J$14))*IF(Dashboard!$L$14="All",1,--(Medical_History[Risk Level]=Dashboard!$L$14))*IF(Dashboard!$N$14="All",1,--(Medical_History[Stroke Label]=Dashboard!$N$14)) )*(--(Medical_History[Smoking Status]=D17))*Medical_History[Stroke Risk Score])/SUMPRODUCT((--(Medical_History[ID]<>"")*IF(Dashboard!$F$12="All",1,--(Medical_History[Gender]=Dashboard!$F$12))*IF(Dashboard!$H$12="All",1,--(Medical_History[Age Group]=Dashboard!$H$12))*IF(Dashboard!$J$12="All",1,--(Medical_History[Region]=Dashboard!$J$12))*IF(Dashboard!$L$12="All",1,--(Medical_History[Smoking Status]=Dashboard!$L$12))*IF(Dashboard!$N$12="All",1,--(Medical_History[Dietary Habits]=Dashboard!$N$12))*IF(Dashboard!$P$12="All",1,--(Medical_History[Alcohol Label]=Dashboard!$P$12))*IF(Dashboard!$F$14="All",1,--(Medical_History[Hypertension Label]=Dashboard!$F$14))*IF(Dashboard!$H$14="All",1,--(Medical_History[Heart Disease Label]=Dashboard!$H$14))*IF(Dashboard!$J$14="All",1,--(Medical_History[Residence Type]=Dashboard!$J$14))*IF(Dashboard!$L$14="All",1,--(Medical_History[Risk Level]=Dashboard!$L$14))*IF(Dashboard!$N$14="All",1,--(Medical_History[Stroke Label]=Dashboard!$N$14)) )*(--(Medical_History[Smoking Status]=D17))),0)} -> 55.5 | F17: {=SUMPRODUCT((--(Medical_History[ID]<>"")*IF(Dashboard!$F$12="All",1,--(Medical_History[Gender]=Dashboard!$F$12))*IF(Dashboard!$H$12="All",1,--(Medical_History[Age Group]=Dashboard!$H$12))*IF(Dashboard!$J$12="All",1,--(Medical_History[Region]=Dashboard!$J$12))*IF(Dashboard!$L$12="All",1,--(Medical_History[Smoking Status]=Dashboard!$L$12))*IF(Dashboard!$N$12="All",1,--(Medical_History[Dietary Habits]=Dashboard!$N$12))*IF(Dashboard!$P$12="All",1,--(Medical_History[Alcohol Label]=Dashboard!$P$12))*IF(Dashboard!$F$14="All",1,--(Medical_History[Hypertension Label]=Dashboard!$F$14))*IF(Dashboard!$H$14="All",1,--(Medical_History[Heart Disease Label]=Dashboard!$H$14))*IF(Dashboard!$J$14="All",1,--(Medical_History[Residence Type]=Dashboard!$J$14))*IF(Dashboard!$L$14="All",1,--(Medical_History[Risk Level]=Dashboard!$L$14))*IF(Dashboard!$N$14="All",1,--(Medical_History[Stroke Label]=Dashboard!$N$14)) )*(--(Medical_History[Smoking Status]=D17)))} -> 24 | H17: Vegetarian | I17: {=IFERROR(SUMPRODUCT((--(Medical_History[ID]<>"")*IF(Dashboard!$F$12="All",1,--(Medical_History[Gender]=Dashboard!$F$12))*IF(Dashboard!$H$12="All",1,--(Medical_History[Age Group]=Dashboard!$H$12))*IF(Dashboard!$J$12="All",1,--(Medical_History[Region]=Dashboard!$J$12))*IF(Dashboard!$L$12="All",1,--(Medical_History[Smoking Status]=Dashboard!$L$12))*IF(Dashboard!$N$12="All",1,--(Medical_History[Dietary Habits]=Dashboard!$N$12))*IF(Dashboard!$P$12="All",1,--(Medical_History[Alcohol Label]=Dashboard!$P$12))*IF(Dashboard!$F$14="All",1,--(Medical_History[Hypertension Label]=Dashboard!$F$14))*IF(Dashboard!$H$14="All",1,--(Medical_History[Heart Disease Label]=Dashboard!$H$14))*IF(Dashboard!$J$14="All",1,--(Medical_History[Residence Type]=Dashboard!$J$14))*IF(Dashboard!$L$14="All",1,--(Medical_History[Risk Level]=Dashboard!$L$14))*IF(Dashboard!$N$14="All",1,--(Medical_History[Stroke Label]=Dashboard!$N$14)) )*(--(Medical_History[Dietary Habits]=H17))*Medical_History[Stroke Risk Score])/SUMPRODUCT((--(Medical_History[ID]<>"")*IF(Dashboard!$F$12="All",1,--(Medical_History[Gender]=Dashboard!$F$12))*IF(Dashboard!$H$12="All",1,--(Medical_History[Age Group]=Dashboard!$H$12))*IF(Dashboard!$J$12="All",1,--(Medical_History[Region]=Dashboard!$J$12))*IF(Dashboard!$L$12="All",1,--(Medical_History[Smoking Status]=Dashboard!$L$12))*IF(Dashboard!$N$12="All",1,--(Medical_History[Dietary Habits]=Dashboard!$N$12))*IF(Dashboard!$P$12="All",1,--(Medical_History[Alcohol Label]=Dashboard!$P$12))*IF(Dashboard!$F$14="All",1,--(Medical_History[Hypertension Label]=Dashboard!$F$14))*IF(Dashboard!$H$14="All",1,--(Medical_History[Heart Disease Label]=Dashboard!$H$14))*IF(Dashboard!$J$14="All",1,--(Medical_History[Residence Type]=Dashboard!$J$14))*IF(Dashboard!$L$14="All",1,--(Medical_History[Risk Level]=Dashboard!$L$14))*IF(Dashboard!$N$14="All",1,--(Medical_History[Stroke Label]=Dashboard!$N$14)) )*(--(Medical_History[Dietary Habits]=H17))),0)} -> 54.071429 | J17: {=SUMPRODUCT((--(Medical_History[ID]<>"")*IF(Dashboard!$F$12="All",1,--(Medical_History[Gender]=Dashboard!$F$12))*IF(Dashboard!$H$12="All",1,--(Medical_History[Age Group]=Dashboard!$H$12))*IF(Dashboard!$J$12="All",1,--(Medical_History[Region]=Dashboard!$J$12))*IF(Dashboard!$L$12="All",1,--(Medical_History[Smoking Status]=Dashboard!$L$12))*IF(Dashboard!$N$12="All",1,--(Medical_History[Dietary Habits]=Dashboard!$N$12))*IF(Dashboard!$P$12="All",1,--(Medical_History[Alcohol Label]=Dashboard!$P$12))*IF(Dashboard!$F$14="All",1,--(Medical_History[Hypertension Label]=Dashboard!$F$14))*IF(Dashboard!$H$14="All",1,--(Medical_History[Heart Disease Label]=Dashboard!$H$14))*IF(Dashboard!$J$14="All",1,--(Medical_History[Residence Type]=Dashboard!$J$14))*IF(Dashboard!$L$14="All",1,--(Medical_History[Risk Level]=Dashboard!$L$14))*IF(Dashboard!$N$14="All",1,--(Medical_History[Stroke Label]=Dashboard!$N$14)) )*(--(Medical_History[Dietary Habits]=H17)))} -> 14 | L17: Consumes Alcohol | M17: {=SUMPRODUCT((--(Medical_History[ID]<>"")*IF(Dashboard!$F$12="All",1,--(Medical_History[Gender]=Dashboard!$F$12))*IF(Dashboard!$H$12="All",1,--(Medical_History[Age Group]=Dashboard!$H$12))*IF(Dashboard!$J$12="All",1,--(Medical_History[Region]=Dashboard!$J$12))*IF(Dashboard!$L$12="All",1,--(Medical_History[Smoking Status]=Dashboard!$L$12))*IF(Dashboard!$N$12="All",1,--(Medical_History[Dietary Habits]=Dashboard!$N$12))*IF(Dashboard!$P$12="All",1,--(Medical_History[Alcohol Label]=Dashboard!$P$12))*IF(Dashboard!$F$14="All",1,--(Medical_History[Hypertension Label]=Dashboard!$F$14))*IF(Dashboard!$H$14="All",1,--(Medical_History[Heart Disease Label]=Dashboard!$H$14))*IF(Dashboard!$J$14="All",1,--(Medical_History[Residence Type]=Dashboard!$J$14))*IF(Dashboard!$L$14="All",1,--(Medical_History[Risk Level]=Dashboard!$L$14))*IF(Dashboard!$N$14="All",1,--(Medical_History[Stroke Label]=Dashboard!$N$14)) )*(--(Medical_History[Alcohol Label]=L17))*Medical_History[Stroke Occurrence])} -> 0 | N17: {=IFERROR(SUMPRODUCT((--(Medical_History[ID]<>"")*IF(Dashboard!$F$12="All",1,--(Medical_History[Gender]=Dashboard!$F$12))*IF(Dashboard!$H$12="All",1,--(Medical_History[Age Group]=Dashboard!$H$12))*IF(Dashboard!$J$12="All",1,--(Medical_History[Region]=Dashboard!$J$12))*IF(Dashboard!$L$12="All",1,--(Medical_History[Smoking Status]=Dashboard!$L$12))*IF(Dashboard!$N$12="All",1,--(Medical_History[Dietary Habits]=Dashboard!$N$12))*IF(Dashboard!$P$12="All",1,--(Medical_History[Alcohol Label]=Dashboard!$P$12))*IF(Dashboard!$F$14="All",1,--(Medical_History[Hypertension Label]=Dashboard!$F$14))*IF(Dashboard!$H$14="All",1,--(Medical_History[Heart Disease Label]=Dashboard!$H$14))*IF(Dashboard!$J$14="All",1,--(Medical_History[Residence Type]=Dashboard!$J$14))*IF(Dashboard!$L$14="All",1,--(Medical_History[Risk Level]=Dashboard!$L$14))*IF(Dashboard!$N$14="All",1,--(Medical_History[Stroke Label]=Dashboard!$N$14)) )*(--(Medical_History[Alcohol Label]=L17))*Medical_History[Stroke Risk Score])/SUMPRODUCT((--(Medical_History[ID]<>"")*IF(Dashboard!$F$12="All",1,--(Medical_History[Gender]=Dashboard!$F$12))*IF(Dashboard!$H$12="All",1,--(Medical_History[Age Group]=Dashboard!$H$12))*IF(Dashboard!$J$12="All",1,--(Medical_History[Region]=Dashboard!$J$12))*IF(Dashboard!$L$12="All",1,--(Medical_History[Smoking Status]=Dashboard!$L$12))*IF(Dashboard!$N$12="All",1,--(Medical_History[Dietary Habits]=Dashboard!$N$12))*IF(Dashboard!$P$12="All",1,--(Medical_History[Alcohol Label]=Dashboard!$P$12))*IF(Dashboard!$F$14="All",1,--(Medical_History[Hypertension Label]=Dashboard!$F$14))*IF(Dashboard!$H$14="All",1,--(Medical_History[Heart Disease Label]=Dashboard!$H$14))*IF(Dashboard!$J$14="All",1,--(Medical_History[Residence Type]=Dashboard!$J$14))*IF(Dashboard!$L$14="All",1,--(Medical_History[Risk Level]=Dashboard!$L$14))*IF(Dashboard!$N$14="All",1,--(Medical_History[Stroke Label]=Dashboard!$N$14)) )*(--(Medical_History[Alcohol Label]=L17))),0)} -> 60.666667
D18: Formerly smoked | E18: {=IFERROR(SUMPRODUCT((--(Medical_History[ID]<>"")*IF(Dashboard!$F$12="All",1,--(Medical_History[Gender]=Dashboard!$F$12))*IF(Dashboard!$H$12="All",1,--(Medical_History[Age Group]=Dashboard!$H$12))*IF(Dashboard!$J$12="All",1,--(Medical_History[Region]=Dashboard!$J$12))*IF(Dashboard!$L$12="All",1,--(Medical_History[Smoking Status]=Dashboard!$L$12))*IF(Dashboard!$N$12="All",1,--(Medical_History[Dietary Habits]=Dashboard!$N$12))*IF(Dashboard!$P$12="All",1,--(Medical_History[Alcohol Label]=Dashboard!$P$12))*IF(Dashboard!$F$14="All",1,--(Medical_History[Hypertension Label]=Dashboard!$F$14))*IF(Dashboard!$H$14="All",1,--(Medical_History[Heart Disease Label]=Dashboard!$H$14))*IF(Dashboard!$J$14="All",1,--(Medical_History[Residence Type]=Dashboard!$J$14))*IF(Dashboard!$L$14="All",1,--(Medical_History[Risk Level]=Dashboard!$L$14))*IF(Dashboard!$N$14="All",1,--(Medical_History[Stroke Label]=Dashboard!$N$14)) )*(--(Medical_History[Smoking Status]=D18))*Medical_History[Stroke Risk Score])/SUMPRODUCT((--(Medical_History[ID]<>"")*IF(Dashboard!$F$12="All",1,--(Medical_History[Gender]=Dashboard!$F$12))*IF(Dashboard!$H$12="All",1,--(Medical_History[Age Group]=Dashboard!$H$12))*IF(Dashboard!$J$12="All",1,--(Medical_History[Region]=Dashboard!$J$12))*IF(Dashboard!$L$12="All",1,--(Medical_History[Smoking Status]=Dashboard!$L$12))*IF(Dashboard!$N$12="All",1,--(Medical_History[Dietary Habits]=Dashboard!$N$12))*IF(Dashboard!$P$12="All",1,--(Medical_History[Alcohol Label]=Dashboard!$P$12))*IF(Dashboard!$F$14="All",1,--(Medical_History[Hypertension Label]=Dashboard!$F$14))*IF(Dashboard!$H$14="All",1,--(Medical_History[Heart Disease Label]=Dashboard!$H$14))*IF(Dashboard!$J$14="All",1,--(Medical_History[Residence Type]=Dashboard!$J$14))*IF(Dashboard!$L$14="All",1,--(Medical_History[Risk Level]=Dashboard!$L$14))*IF(Dashboard!$N$14="All",1,--(Medical_History[Stroke Label]=Dashboard!$N$14)) )*(--(Medical_History[Smoking Status]=D18))),0)} -> 64.125 | F18: {=SUMPRODUCT((--(Medical_History[ID]<>"")*IF(Dashboard!$F$12="All",1,--(Medical_History[Gender]=Dashboard!$F$12))*IF(Dashboard!$H$12="All",1,--(Medical_History[Age Group]=Dashboard!$H$12))*IF(Dashboard!$J$12="All",1,--(Medical_History[Region]=Dashboard!$J$12))*IF(Dashboard!$L$12="All",1,--(Medical_History[Smoking Status]=Dashboard!$L$12))*IF(Dashboard!$N$12="All",1,--(Medical_History[Dietary Habits]=Dashboard!$N$12))*IF(Dashboard!$P$12="All",1,--(Medical_History[Alcohol Label]=Dashboard!$P$12))*IF(Dashboard!$F$14="All",1,--(Medical_History[Hypertension Label]=Dashboard!$F$14))*IF(Dashboard!$H$14="All",1,--(Medical_History[Heart Disease Label]=Dashboard!$H$14))*IF(Dashboard!$J$14="All",1,--(Medical_History[Residence Type]=Dashboard!$J$14))*IF(Dashboard!$L$14="All",1,--(Medical_History[Risk Level]=Dashboard!$L$14))*IF(Dashboard!$N$14="All",1,--(Medical_History[Stroke Label]=Dashboard!$N$14)) )*(--(Medical_History[Smoking Status]=D18)))} -> 8 | H18: Non-Vegetarian | I18: {=IFERROR(SUMPRODUCT((--(Medical_History[ID]<>"")*IF(Dashboard!$F$12="All",1,--(Medical_History[Gender]=Dashboard!$F$12))*IF(Dashboard!$H$12="All",1,--(Medical_History[Age Group]=Dashboard!$H$12))*IF(Dashboard!$J$12="All",1,--(Medical_History[Region]=Dashboard!$J$12))*IF(Dashboard!$L$12="All",1,--(Medical_History[Smoking Status]=Dashboard!$L$12))*IF(Dashboard!$N$12="All",1,--(Medical_History[Dietary Habits]=Dashboard!$N$12))*IF(Dashboard!$P$12="All",1,--(Medical_History[Alcohol Label]=Dashboard!$P$12))*IF(Dashboard!$F$14="All",1,--(Medical_History[Hypertension Label]=Dashboard!$F$14))*IF(Dashboard!$H$14="All",1,--(Medical_History[Heart Disease Label]=Dashboard!$H$14))*IF(Dashboard!$J$14="All",1,--(Medical_History[Residence Type]=Dashboard!$J$14))*IF(Dashboard!$L$14="All",1,--(Medical_History[Risk Level]=Dashboard!$L$14))*IF(Dashboard!$N$14="All",1,--(Medical_History[Stroke Label]=Dashboard!$N$14)) )*(--(Medical_History[Dietary Habits]=H18))*Medical_History[Stroke Risk Score])/SUMPRODUCT((--(Medical_History[ID]<>"")*IF(Dashboard!$F$12="All",1,--(Medical_History[Gender]=Dashboard!$F$12))*IF(Dashboard!$H$12="All",1,--(Medical_History[Age Group]=Dashboard!$H$12))*IF(Dashboard!$J$12="All",1,--(Medical_History[Region]=Dashboard!$J$12))*IF(Dashboard!$L$12="All",1,--(Medical_History[Smoking Status]=Dashboard!$L$12))*IF(Dashboard!$N$12="All",1,--(Medical_History[Dietary Habits]=Dashboard!$N$12))*IF(Dashboard!$P$12="All",1,--(Medical_History[Alcohol Label]=Dashboard!$P$12))*IF(Dashboard!$F$14="All",1,--(Medical_History[Hypertension Label]=Dashboard!$F$14))*IF(Dashboard!$H$14="All",1,--(Medical_History[Heart Disease Label]=Dashboard!$H$14))*IF(Dashboard!$J$14="All",1,--(Medical_History[Residence Type]=Dashboard!$J$14))*IF(Dashboard!$L$14="All",1,--(Medical_History[Risk Level]=Dashboard!$L$14))*IF(Dashboard!$N$14="All",1,--(Medical_History[Stroke Label]=Dashboard!$N$14)) )*(--(Medical_History[Dietary Habits]=H18))),0)} -> 59.470588 | J18: {=SUMPRODUCT((--(Medical_History[ID]<>"")*IF(Dashboard!$F$12="All",1,--(Medical_History[Gender]=Dashboard!$F$12))*IF(Dashboard!$H$12="All",1,--(Medical_History[Age Group]=Dashboard!$H$12))*IF(Dashboard!$J$12="All",1,--(Medical_History[Region]=Dashboard!$J$12))*IF(Dashboard!$L$12="All",1,--(Medical_History[Smoking Status]=Dashboard!$L$12))*IF(Dashboard!$N$12="All",1,--(Medical_History[Dietary Habits]=Dashboard!$N$12))*IF(Dashboard!$P$12="All",1,--(Medical_History[Alcohol Label]=Dashboard!$P$12))*IF(Dashboard!$F$14="All",1,--(Medical_History[Hypertension Label]=Dashboard!$F$14))*IF(Dashboard!$H$14="All",1,--(Medical_History[Heart Disease Label]=Dashboard!$H$14))*IF(Dashboard!$J$14="All",1,--(Medical_History[Residence Type]=Dashboard!$J$14))*IF(Dashboard!$L$14="All",1,--(Medical_History[Risk Level]=Dashboard!$L$14))*IF(Dashboard!$N$14="All",1,--(Medical_History[Stroke Label]=Dashboard!$N$14)) )*(--(Medical_History[Dietary Habits]=H18)))} -> 17 | L18: No Alcohol | M18: {=SUMPRODUCT((--(Medical_History[ID]<>"")*IF(Dashboard!$F$12="All",1,--(Medical_History[Gender]=Dashboard!$F$12))*IF(Dashboard!$H$12="All",1,--(Medical_History[Age Group]=Dashboard!$H$12))*IF(Dashboard!$J$12="All",1,--(Medical_History[Region]=Dashboard!$J$12))*IF(Dashboard!$L$12="All",1,--(Medical_History[Smoking Status]=Dashboard!$L$12))*IF(Dashboard!$N$12="All",1,--(Medical_History[Dietary Habits]=Dashboard!$N$12))*IF(Dashboard!$P$12="All",1,--(Medical_History[Alcohol Label]=Dashboard!$P$12))*IF(Dashboard!$F$14="All",1,--(Medical_History[Hypertension Label]=Dashboard!$F$14))*IF(Dashboard!$H$14="All",1,--(Medical_History[Heart Disease Label]=Dashboard!$H$14))*IF(Dashboard!$J$14="All",1,--(Medical_History[Residence Type]=Dashboard!$J$14))*IF(Dashboard!$L$14="All",1,--(Medical_History[Risk Level]=Dashboard!$L$14))*IF(Dashboard!$N$14="All",1,--(Medical_History[Stroke Label]=Dashboard!$N$14)) )*(--(Medical_History[Alcohol Label]=L18))*Medical_History[Stroke Occurrence])} -> 1 | N18: {=IFERROR(SUMPRODUCT((--(Medical_History[ID]<>"")*IF(Dashboard!$F$12="All",1,--(Medical_History[Gender]=Dashboard!$F$12))*IF(Dashboard!$H$12="All",1,--(Medical_History[Age Group]=Dashboard!$H$12))*IF(Dashboard!$J$12="All",1,--(Medical_History[Region]=Dashboard!$J$12))*IF(Dashboard!$L$12="All",1,--(Medical_History[Smoking Status]=Dashboard!$L$12))*IF(Dashboard!$N$12="All",1,--(Medical_History[Dietary Habits]=Dashboard!$N$12))*IF(Dashboard!$P$12="All",1,--(Medical_History[Alcohol Label]=Dashboard!$P$12))*IF(Dashboard!$F$14="All",1,--(Medical_History[Hypertension Label]=Dashboard!$F$14))*IF(Dashboard!$H$14="All",1,--(Medical_History[Heart Disease Label]=Dashboard!$H$14))*IF(Dashboard!$J$14="All",1,--(Medical_History[Residence Type]=Dashboard!$J$14))*IF(Dashboard!$L$14="All",1,--(Medical_History[Risk Level]=Dashboard!$L$14))*IF(Dashboard!$N$14="All",1,--(Medical_History[Stroke Label]=Dashboard!$N$14)) )*(--(Medical_History[Alcohol Label]=L18))*Medical_History[Stroke Risk Score])/SUMPRODUCT((--(Medical_History[ID]<>"")*IF(Dashboard!$F$12="All",1,--(Medical_History[Gender]=Dashboard!$F$12))*IF(Dashboard!$H$12="All",1,--(Medical_History[Age Group]=Dashboard!$H$12))*IF(Dashboard!$J$12="All",1,--(Medical_History[Region]=Dashboard!$J$12))*IF(Dashboard!$L$12="All",1,--(Medical_History[Smoking Status]=Dashboard!$L$12))*IF(Dashboard!$N$12="All",1,--(Medical_History[Dietary Habits]=Dashboard!$N$12))*IF(Dashboard!$P$12="All",1,--(Medical_History[Alcohol Label]=Dashboard!$P$12))*IF(Dashboard!$F$14="All",1,--(Medical_History[Hypertension Label]=Dashboard!$F$14))*IF(Dashboard!$H$14="All",1,--(Medical_History[Heart Disease Label]=Dashboard!$H$14))*IF(Dashboard!$J$14="All",1,--(Medical_History[Residence Type]=Dashboard!$J$14))*IF(Dashboard!$L$14="All",1,--(Medical_History[Risk Level]=Dashboard!$L$14))*IF(Dashboard!$N$14="All",1,--(Medical_History[Stroke Label]=Dashboard!$N$14)) )*(--(Medical_History[Alcohol Label]=L18))),0)} -> 54.805556
D19: Smokes | E19: {=IFERROR(SUMPRODUCT((--(Medical_History[ID]<>"")*IF(Dashboard!$F$12="All",1,--(Medical_History[Gender]=Dashboard!$F$12))*IF(Dashboard!$H$12="All",1,--(Medical_History[Age Group]=Dashboard!$H$12))*IF(Dashboard!$J$12="All",1,--(Medical_History[Region]=Dashboard!$J$12))*IF(Dashboard!$L$12="All",1,--(Medical_History[Smoking Status]=Dashboard!$L$12))*IF(Dashboard!$N$12="All",1,--(Medical_History[Dietary Habits]=Dashboard!$N$12))*IF(Dashboard!$P$12="All",1,--(Medical_History[Alcohol Label]=Dashboard!$P$12))*IF(Dashboard!$F$14="All",1,--(Medical_History[Hypertension Label]=Dashboard!$F$14))*IF(Dashboard!$H$14="All",1,--(Medical_History[Heart Disease Label]=Dashboard!$H$14))*IF(Dashboard!$J$14="All",1,--(Medical_History[Residence Type]=Dashboard!$J$14))*IF(Dashboard!$L$14="All",1,--(Medical_History[Risk Level]=Dashboard!$L$14))*IF(Dashboard!$N$14="All",1,--(Medical_History[Stroke Label]=Dashboard!$N$14)) )*(--(Medical_History[Smoking Status]=D19))*Medical_History[Stroke Risk Score])/SUMPRODUCT((--(Medical_History[ID]<>"")*IF(Dashboard!$F$12="All",1,--(Medical_History[Gender]=Dashboard!$F$12))*IF(Dashboard!$H$12="All",1,--(Medical_History[Age Group]=Dashboard!$H$12))*IF(Dashboard!$J$12="All",1,--(Medical_History[Region]=Dashboard!$J$12))*IF(Dashboard!$L$12="All",1,--(Medical_History[Smoking Status]=Dashboard!$L$12))*IF(Dashboard!$N$12="All",1,--(Medical_History[Dietary Habits]=Dashboard!$N$12))*IF(Dashboard!$P$12="All",1,--(Medical_History[Alcohol Label]=Dashboard!$P$12))*IF(Dashboard!$F$14="All",1,--(Medical_History[Hypertension Label]=Dashboard!$F$14))*IF(Dashboard!$H$14="All",1,--(Medical_History[Heart Disease Label]=Dashboard!$H$14))*IF(Dashboard!$J$14="All",1,--(Medical_History[Residence Type]=Dashboard!$J$14))*IF(Dashboard!$L$14="All",1,--(Medical_History[Risk Level]=Dashboard!$L$14))*IF(Dashboard!$N$14="All",1,--(Medical_History[Stroke Label]=Dashboard!$N$14)) )*(--(Medical_History[Smoking Status]=D19))),0)} -> 35.666667 | F19: {=SUMPRODUCT((--(Medical_History[ID]<>"")*IF(Dashboard!$F$12="All",1,--(Medical_History[Gender]=Dashboard!$F$12))*IF(Dashboard!$H$12="All",1,--(Medical_History[Age Group]=Dashboard!$H$12))*IF(Dashboard!$J$12="All",1,--(Medical_History[Region]=Dashboard!$J$12))*IF(Dashboard!$L$12="All",1,--(Medical_History[Smoking Status]=Dashboard!$L$12))*IF(Dashboard!$N$12="All",1,--(Medical_History[Dietary Habits]=Dashboard!$N$12))*IF(Dashboard!$P$12="All",1,--(Medical_History[Alcohol Label]=Dashboard!$P$12))*IF(Dashboard!$F$14="All",1,--(Medical_History[Hypertension Label]=Dashboard!$F$14))*IF(Dashboard!$H$14="All",1,--(Medical_History[Heart Disease Label]=Dashboard!$H$14))*IF(Dashboard!$J$14="All",1,--(Medical_History[Residence Type]=Dashboard!$J$14))*IF(Dashboard!$L$14="All",1,--(Medical_History[Risk Level]=Dashboard!$L$14))*IF(Dashboard!$N$14="All",1,--(Medical_History[Stroke Label]=Dashboard!$N$14)) )*(--(Medical_History[Smoking Status]=D19)))} -> 6
A22: Medical Condition | B22: Avg Risk - Yes | C22: Avg Risk - No
A23: Hypertension | B23: {=IFERROR(SUMPRODUCT((--(Medical_History[ID]<>"")*IF(Dashboard!$F$12="All",1,--(Medical_History[Gender]=Dashboard!$F$12))*IF(Dashboard!$H$12="All",1,--(Medical_History[Age Group]=Dashboard!$H$12))*IF(Dashboard!$J$12="All",1,--(Medical_History[Region]=Dashboard!$J$12))*IF(Dashboard!$L$12="All",1,--(Medical_History[Smoking Status]=Dashboard!$L$12))*IF(Dashboard!$N$12="All",1,--(Medical_History[Dietary Habits]=Dashboard!$N$12))*IF(Dashboard!$P$12="All",1,--(Medical_History[Alcohol Label]=Dashboard!$P$12))*IF(Dashboard!$F$14="All",1,--(Medical_History[Hypertension Label]=Dashboard!$F$14))*IF(Dashboard!$H$14="All",1,--(Medical_History[Heart Disease Label]=Dashboard!$H$14))*IF(Dashboard!$J$14="All",1,--(Medical_History[Residence Type]=Dashboard!$J$14))*IF(Dashboard!$L$14="All",1,--(Medical_History[Risk Level]=Dashboard!$L$14))*IF(Dashboard!$N$14="All",1,--(Medical_History[Stroke Label]=Dashboard!$N$14)) )*(--(Medical_History[Hypertension Label]="Yes"))*Medical_History[Stroke Risk Score])/SUMPRODUCT((--(Medical_History[ID]<>"")*IF(Dashboard!$F$12="All",1,--(Medical_History[Gender]=Dashboard!$F$12))*IF(Dashboard!$H$12="All",1,--(Medical_History[Age Group]=Dashboard!$H$12))*IF(Dashboard!$J$12="All",1,--(Medical_History[Region]=Dashboard!$J$12))*IF(Dashboard!$L$12="All",1,--(Medical_History[Smoking Status]=Dashboard!$L$12))*IF(Dashboard!$N$12="All",1,--(Medical_History[Dietary Habits]=Dashboard!$N$12))*IF(Dashboard!$P$12="All",1,--(Medical_History[Alcohol Label]=Dashboard!$P$12))*IF(Dashboard!$F$14="All",1,--(Medical_History[Hypertension Label]=Dashboard!$F$14))*IF(Dashboard!$H$14="All",1,--(Medical_History[Heart Disease Label]=Dashboard!$H$14))*IF(Dashboard!$J$14="All",1,--(Medical_History[Residence Type]=Dashboard!$J$14))*IF(Dashboard!$L$14="All",1,--(Medical_History[Risk Level]=Dashboard!$L$14))*IF(Dashboard!$N$14="All",1,--(Medical_History[Stroke Label]=Dashboard!$N$14)) )*(--(Medical_History[Hypertension Label]="Yes"))),0)} -> 40.8 | C23: {=IFERROR(SUMPRODUCT((--(Medical_History[ID]<>"")*IF(Dashboard!$F$12="All",1,--(Medical_History[Gender]=Dashboard!$F$12))*IF(Dashboard!$H$12="All",1,--(Medical_History[Age Group]=Dashboard!$H$12))*IF(Dashboard!$J$12="All",1,--(Medical_History[Region]=Dashboard!$J$12))*IF(Dashboard!$L$12="All",1,--(Medical_History[Smoking Status]=Dashboard!$L$12))*IF(Dashboard!$N$12="All",1,--(Medical_History[Dietary Habits]=Dashboard!$N$12))*IF(Dashboard!$P$12="All",1,--(Medical_History[Alcohol Label]=Dashboard!$P$12))*IF(Dashboard!$F$14="All",1,--(Medical_History[Hypertension Label]=Dashboard!$F$14))*IF(Dashboard!$H$14="All",1,--(Medical_History[Heart Disease Label]=Dashboard!$H$14))*IF(Dashboard!$J$14="All",1,--(Medical_History[Residence Type]=Dashboard!$J$14))*IF(Dashboard!$L$14="All",1,--(Medical_History[Risk Level]=Dashboard!$L$14))*IF(Dashboard!$N$14="All",1,--(Medical_History[Stroke Label]=Dashboard!$N$14)) )*(--(Medical_History[Hypertension Label]="No"))*Medical_History[Stroke Risk Score])/SUMPRODUCT((--(Medical_History[ID]<>"")*IF(Dashboard!$F$12="All",1,--(Medical_History[Gender]=Dashboard!$F$12))*IF(Dashboard!$H$12="All",1,--(Medical_History[Age Group]=Dashboard!$H$12))*IF(Dashboard!$J$12="All",1,--(Medical_History[Region]=Dashboard!$J$12))*IF(Dashboard!$L$12="All",1,--(Medical_History[Smoking Status]=Dashboard!$L$12))*IF(Dashboard!$N$12="All",1,--(Medical_History[Dietary Habits]=Dashboard!$N$12))*IF(Dashboard!$P$12="All",1,--(Medical_History[Alcohol Label]=Dashboard!$P$12))*IF(Dashboard!$F$14="All",1,--(Medical_History[Hypertension Label]=Dashboard!$F$14))*IF(Dashboard!$H$14="All",1,--(Medical_History[Heart Disease Label]=Dashboard!$H$14))*IF(Dashboard!$J$14="All",1,--(Medical_History[Residence Type]=Dashboard!$J$14))*IF(Dashboard!$L$14="All",1,--(Medical_History[Risk Level]=Dashboard!$L$14))*IF(Dashboard!$N$14="All",1,--(Medical_History[Stroke Label]=Dashboard!$N$14)) )*(--(Medical_History[Hypertension Label]="No"))),0)} -> 57.382353
A24: Heart Disease | B24: {=IFERROR(SUMPRODUCT((--(Medical_History[ID]<>"")*IF(Dashboard!$F$12="All",1,--(Medical_History[Gender]=Dashboard!$F$12))*IF(Dashboard!$H$12="All",1,--(Medical_History[Age Group]=Dashboard!$H$12))*IF(Dashboard!$J$12="All",1,--(Medical_History[Region]=Dashboard!$J$12))*IF(Dashboard!$L$12="All",1,--(Medical_History[Smoking Status]=Dashboard!$L$12))*IF(Dashboard!$N$12="All",1,--(Medical_History[Dietary Habits]=Dashboard!$N$12))*IF(Dashboard!$P$12="All",1,--(Medical_History[Alcohol Label]=Dashboard!$P$12))*IF(Dashboard!$F$14="All",1,--(Medical_History[Hypertension Label]=Dashboard!$F$14))*IF(Dashboard!$H$14="All",1,--(Medical_History[Heart Disease Label]=Dashboard!$H$14))*IF(Dashboard!$J$14="All",1,--(Medical_History[Residence Type]=Dashboard!$J$14))*IF(Dashboard!$L$14="All",1,--(Medical_History[Risk Level]=Dashboard!$L$14))*IF(Dashboard!$N$14="All",1,--(Medical_History[Stroke Label]=Dashboard!$N$14)) )*(--(Medical_History[Heart Disease Label]="Yes"))*Medical_History[Stroke Risk Score])/SUMPRODUCT((--(Medical_History[ID]<>"")*IF(Dashboard!$F$12="All",1,--(Medical_History[Gender]=Dashboard!$F$12))*IF(Dashboard!$H$12="All",1,--(Medical_History[Age Group]=Dashboard!$H$12))*IF(Dashboard!$J$12="All",1,--(Medical_History[Region]=Dashboard!$J$12))*IF(Dashboard!$L$12="All",1,--(Medical_History[Smoking Status]=Dashboard!$L$12))*IF(Dashboard!$N$12="All",1,--(Medical_History[Dietary Habits]=Dashboard!$N$12))*IF(Dashboard!$P$12="All",1,--(Medical_History[Alcohol Label]=Dashboard!$P$12))*IF(Dashboard!$F$14="All",1,--(Medical_History[Hypertension Label]=Dashboard!$F$14))*IF(Dashboard!$H$14="All",1,--(Medical_History[Heart Disease Label]=Dashboard!$H$14))*IF(Dashboard!$J$14="All",1,--(Medical_History[Residence Type]=Dashboard!$J$14))*IF(Dashboard!$L$14="All",1,--(Medical_History[Risk Level]=Dashboard!$L$14))*IF(Dashboard!$N$14="All",1,--(Medical_History[Stroke Label]=Dashboard!$N$14)) )*(--(Medical_History[Heart Disease Label]="Yes"))),0)} -> 44 | C24: {=IFERROR(SUMPRODUCT((--(Medical_History[ID]<>"")*IF(Dashboard!$F$12="All",1,--(Medical_History[Gender]=Dashboard!$F$12))*IF(Dashboard!$H$12="All",1,--(Medical_History[Age Group]=Dashboard!$H$12))*IF(Dashboard!$J$12="All",1,--(Medical_History[Region]=Dashboard!$J$12))*IF(Dashboard!$L$12="All",1,--(Medical_History[Smoking Status]=Dashboard!$L$12))*IF(Dashboard!$N$12="All",1,--(Medical_History[Dietary Habits]=Dashboard!$N$12))*IF(Dashboard!$P$12="All",1,--(Medical_History[Alcohol Label]=Dashboard!$P$12))*IF(Dashboard!$F$14="All",1,--(Medical_History[Hypertension Label]=Dashboard!$F$14))*IF(Dashboard!$H$14="All",1,--(Medical_History[Heart Disease Label]=Dashboard!$H$14))*IF(Dashboard!$J$14="All",1,--(Medical_History[Residence Type]=Dashboard!$J$14))*IF(Dashboard!$L$14="All",1,--(Medical_History[Risk Level]=Dashboard!$L$14))*IF(Dashboard!$N$14="All",1,--(Medical_History[Stroke Label]=Dashboard!$N$14)) )*(--(Medical_History[Heart Disease Label]="No"))*Medical_History[Stroke Risk Score])/SUMPRODUCT((--(Medical_History[ID]<>"")*IF(Dashboard!$F$12="All",1,--(Medical_History[Gender]=Dashboard!$F$12))*IF(Dashboard!$H$12="All",1,--(Medical_History[Age Group]=Dashboard!$H$12))*IF(Dashboard!$J$12="All",1,--(Medical_History[Region]=Dashboard!$J$12))*IF(Dashboard!$L$12="All",1,--(Medical_History[Smoking Status]=Dashboard!$L$12))*IF(Dashboard!$N$12="All",1,--(Medical_History[Dietary Habits]=Dashboard!$N$12))*IF(Dashboard!$P$12="All",1,--(Medical_History[Alcohol Label]=Dashboard!$P$12))*IF(Dashboard!$F$14="All",1,--(Medical_History[Hypertension Label]=Dashboard!$F$14))*IF(Dashboard!$H$14="All",1,--(Medical_History[Heart Disease Label]=Dashboard!$H$14))*IF(Dashboard!$J$14="All",1,--(Medical_History[Residence Type]=Dashboard!$J$14))*IF(Dashboard!$L$14="All",1,--(Medical_History[Risk Level]=Dashboard!$L$14))*IF(Dashboard!$N$14="All",1,--(Medical_History[Stroke Label]=Dashboard!$N$14)) )*(--(Medical_History[Heart Disease Label]="No"))),0)} -> 55.864865
A27: Condition | B27: Status | C27: Stroke Cases | D27: Avg Risk
